Workbook

Sheet LEIA-ME
A1: MHBV-02A · Modelo Financeiro da Cooperativa · MHBV 071026 (07/10/2026) (Entreposto Regional)
A3: Modelo do Entreposto Regional: 630 m² úteis / ≈ 666 m² construídos (decisão D1, 07/10/2026 — MHBV-18), 350 t de capacidade, 250 t de regime, Crédito Híbrido FNE (investimento + giro renovável) + capital próprio.
A4: Azul = premissa editável (aba Premissas). Preto = fórmula. Tudo recalcula sozinho.
A5: Cobertura da dívida = (EBITDA + retenção de 5%) ÷ (juros + amortização do FNE investimento + juros do FNE giro).
A6: FNE giro renovável a cada safra: só os juros entram no serviço da dívida; o principal volta com a venda do estoque (CONFIRMAR COM BNB).
A7: Itens marcados ESTIMATIVA ou PREMISSA precisam de cotação/orçamento real antes do protocolo no BNB.
A8: Abas: Premissas · Pessoal · Fluxo · Resumo · Giro · Cenarios_BNB.

Sheet Premissas
A1: PREMISSAS · Entreposto Regional MEL-HORANDO (MHBV-02A · MHBV 071026 (07/10/2026))
A3: Premissa | B3: Valor | C3: Unidade | D3: Fonte / observação
A5: CHAVES DE CENÁRIO (sensibilidade)
A6: Fator sobre o preço do mel (venda e, por indexação, preço ao cooperado) | B6: 1 | C6: × | D6: 1,00 = base; 0,80 = mel −20%.
A7: Fator sobre o volume recebido | B7: 1 | C7: × | D7: 1,00 = base.
A8: Fator sobre o investimento | B8: 1 | C8: × | D8: 1,00 = base.
A10: INVESTIMENTO E FINANCIAMENTO
A11: Obras civis (630 m² úteis / ≈ 666 m² construídos, fluxo em 1 direção – Port. SDA/MAPA 795/2023) | B11: 1791560 | C11: R$ | D11: Decisão D1 (07/10/2026): MHBV-18 Cenário 2 — orçado por tipo de área (R$ 1.353.700) + 6% estrutura (R$ 79.548) + BDI 25% = R$ 1.791.560. Preços unitários REQUEREM VERIFICAÇÃO EXTERNA; substituir pelo projeto executivo (fev/2027). Antes: R$ 1,30 mi (550 m², sem BDI).
A12: Equipamentos de processo + laboratório local (IN MAPA 11/2000) | B12: 1690000 | C12: R$ | D12: Preços unitários do projeto técnico anterior (1 linha + envase de sachê + lab básico), sem cotação. Validar com 3 orçamentos por item.
A13: Projetos, licenças, instalação e imprevistos | B13: 350000 | C13: R$ | D13: ESTIMATIVA (≈ 10% de obra + equipamentos) — MHBV-18 §5.
A14: Investimento total no cenário | B14: =(Premissas!$B$11+Premissas!$B$12+Premissas!$B$13)*Premissas!$B$8 -> 3831560 | C14: R$ | D14: Fórmula. Base = R$ 3,83 mi (antes R$ 3,29 mi).
A15: FNE investimento (Coopera) | B15: =MIN(2000000,Premissas!$B$14*0.8) -> 2000000 | C15: R$ | D15: Pleito: R$ 2,0 mi (≈ 52%) — teto pela cobertura ≥ 1,50x com mel −20% (MHBV-18 §6). Contrapartida R$ 1,83 mi (≈ 48%).
A16: Taxa de juros FNE | B16: 0.1 | C16: % a.a. | D16: Premissa: meio da faixa 7,65%–12,45% a.a. CONFIRMAR COM BNB.
A17: Prazo total FNE investimento | B17: 12 | C17: anos | D17: FNE Coopera – investimento fixo: até 12 anos (bnb.gov.br).
A18: Carência (só juros) | B18: 4 | C18: anos | D18: Até 4 anos.
A19: Fração de ano de juros durante a obra (ano 0) | B19: 0.5 | C19: ano | D19: Liberação em parcelas.
A21: VOLUME (t de mel recebidas dos cooperados)
A22: Capacidade instalada | B22: 350 | C22: t/ano | D22: Projeto do entreposto.
A23: Volume ano 1 da planta | B23: 200 | C23: t | D23: Piloto SIE (Fase 0, imóvel locado): 150 t (2027) → 200 t (2028). Planta abre na transição.
A24: Volume ano 2 da planta | B24: 250 | C24: t | D24: Regime (250 t) a partir do ano 2 da planta = ano 3 desde o início do piloto.
A25: Volume ano 3 em diante | B25: 250 | C25: t | D25: IBGE/PPM 2024: Boa Viagem + 16 municípios (Anexo I fechado, campo 17 = Banabuiú — decisão D4) = 521 t.
A26: Perda de processo (filtração, borra, amostras) | B26: 0.015 | C26: % | D26: Premissa técnica; validar com o RT.
A27: Parcela vendida em sachê (400 g / 700 g / 1,4 kg) | B27: 0.6 | C27: % | D27: Mix 60% sachê / 40% granel.
A29: PREÇOS (R$/kg)
A30: Preço médio do sachê (atacado, sem frete) | B30: 30 | C30: R$/kg | D30: PREMISSA A VALIDAR com cartas de intenção de compradores.
A31: Preço do granel no mercado interno (índice PAA/Conab-CE) | B31: 18.55 | C31: R$/kg | D31: Índice de referência do Regimento (o CEPEA não publica mel). Atualizar na data do protocolo.
A32: Percentual pago ao cooperado sobre o granel | B32: 0.65 | C32: % | D32: Decisão 30/09/2026: 65% (cobertura ≥ 1,5x com mel −20%). Regimento 00C, item 3.
A33: Preço ao cooperado | B33: =Premissas!$B$32*Premissas!$B$31*Premissas!$B$6 -> 12.0575 | C33: R$/kg | D33: Fórmula: 65% × 18,55 = R$ 12,06/kg na base.
A34: Parte paga na entrega | B34: 0.5 | C34: % | D34: Regimento: 50% na entrega.
A35: Parte paga em 90 dias | B35: 0.2 | C35: % | D35: Regimento: 20% em 90 dias; saldo como sobra no fim do exercício.
A36: Retenção de capital sobre o mel entregue | B36: 0.05 | C36: % | D36: Cota-parte (Estatuto/Regimento). Fica na Cooperativa.
A37: Preço pago pelo atravessador (referência) | B37: 12 | C37: R$/kg | D37: Portal LJ, 23/07/2025 ("já chegou a R$ 12"). Só para o indicador social.
A39: CUSTOS VARIÁVEIS
A40: Embalagem do sachê (filme, caixa, rótulo) | B40: 1.3 | C40: R$/kg | D40: Premissa; cotar.
A41: Tambor com verniz sanitário (granel) | B41: 1.2 | C41: R$/kg | D41: Premissa.
A42: Frete de entrega do sachê | B42: 0.05 | C42: % rec. sachê | D42: Premissa (CE; venda só no CE até o SIF).
A43: Frete do granel | B43: 0.25 | C43: R$/kg | D43: Premissa.
A44: Comercial e marketing do sachê | B44: 0.03 | C44: % rec. sachê | D44: Premissa.
A45: Licença da marca Fiore di Campo | B45: 0.02 | C45: % rec. sachê | D45: Parte relacionada: AGE + preço de mercado.
A46: Energia e água de processo | B46: 0.1 | C46: R$/kg | D46: Premissa.
...

Sheet Pessoal
A1: PESSOAL · quadro enxuto do entreposto (CLT: salário × 13,33 × (1+35,8%) + R$ 400/mês)
A3: Setor | B3: Função | C3: Qtd. | D3: Salário mensal (R$) | E3: Tipo | F3: Custo anual (R$)
A4: Gestão | B4: Gerente do entreposto | C4: 1 | D4: 5500 | E4: CLT | F4: =C4*(D4*13.33*(1+0.358)+400*12) -> 104361.77
A5: Gestão | B5: Assistente administrativo-financeiro | C5: 1 | D5: 2800 | E5: CLT | F5: =C5*(D5*13.33*(1+0.358)+400*12) -> 55485.992
A6: Qualidade | B6: Técnico de laboratório / monitor de BPF | C6: 1 | D6: 2800 | E6: CLT | F6: =C6*(D6*13.33*(1+0.358)+400*12) -> 55485.992
A7: Produção | B7: Operador de recepção e beneficiamento | C7: 2 | D7: 1900 | E7: CLT | F7: =C7*(D7*13.33*(1+0.358)+400*12) -> 78388.132
A8: Produção | B8: Operador de envase e rotulagem | C8: 2 | D8: 1800 | E8: CLT | F8: =C8*(D8*13.33*(1+0.358)+400*12) -> 74767.704
A9: Produção | B9: Auxiliar de higienização | C9: 1 | D9: 1700 | E9: CLT | F9: =C9*(D9*13.33*(1+0.358)+400*12) -> 35573.638
A10: Logística | B10: Auxiliar de expedição / motorista | C10: 1 | D10: 2200 | E10: CLT | F10: =C10*(D10*13.33*(1+0.358)+400*12) -> 44624.708
A11: Comercial | B11: Vendedor (CE) | C11: 1 | D11: 3000 | E11: CLT | F11: =C11*(D11*13.33*(1+0.358)+400*12) -> 59106.42
B14: TOTAL | C14: =SUM(C4:C11) -> 10 | F14: =SUM(F4:F11) -> 507794.36
A16: RT fica fora do quadro: contrato de prestação de serviço (Premissas). Salários = premissa a validar.

Sheet Fluxo
A1: FLUXO ANUAL · ano 0 = obra · anos 1 a 12 = operação (R$)
A3: Linha | B3: Ano 0 | C3: Ano 1 | D3: Ano 2 | E3: Ano 3 | F3: Ano 4 | G3: Ano 5 | H3: Ano 6 | I3: Ano 7 | J3: Ano 8 | K3: Ano 9 | L3: Ano 10 | M3: Ano 11 | N3: Ano 12
A4: Volume recebido (t) | B4: 0 | C4: =IF(1=1,Premissas!$B$23,IF(1=2,Premissas!$B$24,Premissas!$B$25))*Premissas!$B$7 -> 200 | D4: =IF(2=1,Premissas!$B$23,IF(2=2,Premissas!$B$24,Premissas!$B$25))*Premissas!$B$7 -> 250 | E4: =IF(3=1,Premissas!$B$23,IF(3=2,Premissas!$B$24,Premissas!$B$25))*Premissas!$B$7 -> 250 | F4: =IF(4=1,Premissas!$B$23,IF(4=2,Premissas!$B$24,Premissas!$B$25))*Premissas!$B$7 -> 250 | G4: =IF(5=1,Premissas!$B$23,IF(5=2,Premissas!$B$24,Premissas!$B$25))*Premissas!$B$7 -> 250 | H4: =IF(6=1,Premissas!$B$23,IF(6=2,Premissas!$B$24,Premissas!$B$25))*Premissas!$B$7 -> 250 | I4: =IF(7=1,Premissas!$B$23,IF(7=2,Premissas!$B$24,Premissas!$B$25))*Premissas!$B$7 -> 250 | J4: =IF(8=1,Premissas!$B$23,IF(8=2,Premissas!$B$24,Premissas!$B$25))*Premissas!$B$7 -> 250 | K4: =IF(9=1,Premissas!$B$23,IF(9=2,Premissas!$B$24,Premissas!$B$25))*Premissas!$B$7 -> 250 | L4: =IF(10=1,Premissas!$B$23,IF(10=2,Premissas!$B$24,Premissas!$B$25))*Premissas!$B$7 -> 250 | M4: =IF(11=1,Premissas!$B$23,IF(11=2,Premissas!$B$24,Premissas!$B$25))*Premissas!$B$7 -> 250 | N4: =IF(12=1,Premissas!$B$23,IF(12=2,Premissas!$B$24,Premissas!$B$25))*Premissas!$B$7 -> 250
A5: Uso da capacidade | B5: 0 | C5: =C4/Premissas!$B$22 -> 0.57142857 | D5: =D4/Premissas!$B$22 -> 0.71428571 | E5: =E4/Premissas!$B$22 -> 0.71428571 | F5: =F4/Premissas!$B$22 -> 0.71428571 | G5: =G4/Premissas!$B$22 -> 0.71428571 | H5: =H4/Premissas!$B$22 -> 0.71428571 | I5: =I4/Premissas!$B$22 -> 0.71428571 | J5: =J4/Premissas!$B$22 -> 0.71428571 | ... N5: =N4/Premissas!$B$22 -> 0.71428571
A6: Volume vendido (t) | B6: =B4*(1-Premissas!$B$26) -> 0 | C6: =C4*(1-Premissas!$B$26) -> 197 | D6: =D4*(1-Premissas!$B$26) -> 246.25 | E6: =E4*(1-Premissas!$B$26) -> 246.25 | F6: =F4*(1-Premissas!$B$26) -> 246.25 | G6: =G4*(1-Premissas!$B$26) -> 246.25 | H6: =H4*(1-Premissas!$B$26) -> 246.25 | I6: =I4*(1-Premissas!$B$26) -> 246.25 | ... N6: =N4*(1-Premissas!$B$26) -> 246.25
A7: Sachê (t) | B7: =B6*Premissas!$B$27 -> 0 | C7: =C6*Premissas!$B$27 -> 118.2 | D7: =D6*Premissas!$B$27 -> 147.75 | E7: =E6*Premissas!$B$27 -> 147.75 | F7: =F6*Premissas!$B$27 -> 147.75 | G7: =G6*Premissas!$B$27 -> 147.75 | H7: =H6*Premissas!$B$27 -> 147.75 | I7: =I6*Premissas!$B$27 -> 147.75 | ... N7: =N6*Premissas!$B$27 -> 147.75
A8: Granel (t) | B8: =B6*(1-Premissas!$B$27) -> 0 | C8: =C6*(1-Premissas!$B$27) -> 78.8 | D8: =D6*(1-Premissas!$B$27) -> 98.5 | E8: =E6*(1-Premissas!$B$27) -> 98.5 | F8: =F6*(1-Premissas!$B$27) -> 98.5 | G8: =G6*(1-Premissas!$B$27) -> 98.5 | H8: =H6*(1-Premissas!$B$27) -> 98.5 | I8: =I6*(1-Premissas!$B$27) -> 98.5 | ... N8: =N6*(1-Premissas!$B$27) -> 98.5
A10: Receita sachê | B10: =B7*1000*Premissas!$B$30*Premissas!$B$6 -> 0 | C10: =C7*1000*Premissas!$B$30*Premissas!$B$6 -> 3546000 | D10: =D7*1000*Premissas!$B$30*Premissas!$B$6 -> 4432500 | E10: =E7*1000*Premissas!$B$30*Premissas!$B$6 -> 4432500 | F10: =F7*1000*Premissas!$B$30*Premissas!$B$6 -> 4432500 | G10: =G7*1000*Premissas!$B$30*Premissas!$B$6 -> 4432500 | H10: =H7*1000*Premissas!$B$30*Premissas!$B$6 -> 4432500 | I10: =I7*1000*Premissas!$B$30*Premissas!$B$6 -> 4432500 | ... N10: =N7*1000*Premissas!$B$30*Premissas!$B$6 -> 4432500
A11: Receita granel | B11: =B8*1000*Premissas!$B$31*Premissas!$B$6 -> 0 | C11: =C8*1000*Premissas!$B$31*Premissas!$B$6 -> 1461740 | D11: =D8*1000*Premissas!$B$31*Premissas!$B$6 -> 1827175 | E11: =E8*1000*Premissas!$B$31*Premissas!$B$6 -> 1827175 | F11: =F8*1000*Premissas!$B$31*Premissas!$B$6 -> 1827175 | G11: =G8*1000*Premissas!$B$31*Premissas!$B$6 -> 1827175 | H11: =H8*1000*Premissas!$B$31*Premissas!$B$6 -> 1827175 | I11: =I8*1000*Premissas!$B$31*Premissas!$B$6 -> 1827175 | ... N11: =N8*1000*Premissas!$B$31*Premissas!$B$6 -> 1827175
A12: RECEITA BRUTA | B12: =B10+B11 -> 0 | C12: =C10+C11 -> 5007740 | D12: =D10+D11 -> 6259675 | E12: =E10+E11 -> 6259675 | F12: =F10+F11 -> 6259675 | G12: =G10+G11 -> 6259675 | H12: =H10+H11 -> 6259675 | I12: =I10+I11 -> 6259675 | ... N12: =N10+N11 -> 6259675
A13: Tributos sobre vendas | B13: =-B12*Premissas!$B$47 -> 0 | C13: =-C12*Premissas!$B$47 -> -350541.8 | D13: =-D12*Premissas!$B$47 -> -438177.25 | E13: =-E12*Premissas!$B$47 -> -438177.25 | F13: =-F12*Premissas!$B$47 -> -438177.25 | G13: =-G12*Premissas!$B$47 -> -438177.25 | H13: =-H12*Premissas!$B$47 -> -438177.25 | I13: =-I12*Premissas!$B$47 -> -438177.25 | ... N13: =-N12*Premissas!$B$47 -> -438177.25
A15: Mel pago ao cooperado (valor total) | B15: =-B4*1000*Premissas!$B$33 -> 0 | C15: =-C4*1000*Premissas!$B$33 -> -2411500 | D15: =-D4*1000*Premissas!$B$33 -> -3014375 | E15: =-E4*1000*Premissas!$B$33 -> -3014375 | F15: =-F4*1000*Premissas!$B$33 -> -3014375 | G15: =-G4*1000*Premissas!$B$33 -> -3014375 | H15: =-H4*1000*Premissas!$B$33 -> -3014375 | I15: =-I4*1000*Premissas!$B$33 -> -3014375 | ... N15: =-N4*1000*Premissas!$B$33 -> -3014375
A16: Embalagem sachê + tambor | B16: =-(B7*1000*Premissas!$B$40+B8*1000*Premissas!$B$41) -> 0 | C16: =-(C7*1000*Premissas!$B$40+C8*1000*Premissas!$B$41) -> -248220 | D16: =-(D7*1000*Premissas!$B$40+D8*1000*Premissas!$B$41) -> -310275 | E16: =-(E7*1000*Premissas!$B$40+E8*1000*Premissas!$B$41) -> -310275 | F16: =-(F7*1000*Premissas!$B$40+F8*1000*Premissas!$B$41) -> -310275 | G16: =-(G7*1000*Premissas!$B$40+G8*1000*Premissas!$B$41) -> -310275 | H16: =-(H7*1000*Premissas!$B$40+H8*1000*Premissas!$B$41) -> -310275 | I16: =-(I7*1000*Premissas!$B$40+I8*1000*Premissas!$B$41) -> -310275 | ... N16: =-(N7*1000*Premissas!$B$40+N8*1000*Premissas!$B$41) -> -310275
A17: Fretes | B17: =-(B10*Premissas!$B$42+B8*1000*Premissas!$B$43) -> 0 | C17: =-(C10*Premissas!$B$42+C8*1000*Premissas!$B$43) -> -197000 | D17: =-(D10*Premissas!$B$42+D8*1000*Premissas!$B$43) -> -246250 | E17: =-(E10*Premissas!$B$42+E8*1000*Premissas!$B$43) -> -246250 | F17: =-(F10*Premissas!$B$42+F8*1000*Premissas!$B$43) -> -246250 | G17: =-(G10*Premissas!$B$42+G8*1000*Premissas!$B$43) -> -246250 | H17: =-(H10*Premissas!$B$42+H8*1000*Premissas!$B$43) -> -246250 | I17: =-(I10*Premissas!$B$42+I8*1000*Premissas!$B$43) -> -246250 | ... N17: =-(N10*Premissas!$B$42+N8*1000*Premissas!$B$43) -> -246250
A18: Comercial + licença de marca | B18: =-B10*(Premissas!$B$44+Premissas!$B$45) -> 0 | C18: =-C10*(Premissas!$B$44+Premissas!$B$45) -> -177300 | D18: =-D10*(Premissas!$B$44+Premissas!$B$45) -> -221625 | E18: =-E10*(Premissas!$B$44+Premissas!$B$45) -> -221625 | F18: =-F10*(Premissas!$B$44+Premissas!$B$45) -> -221625 | G18: =-G10*(Premissas!$B$44+Premissas!$B$45) -> -221625 | H18: =-H10*(Premissas!$B$44+Premissas!$B$45) -> -221625 | I18: =-I10*(Premissas!$B$44+Premissas!$B$45) -> -221625 | ... N18: =-N10*(Premissas!$B$44+Premissas!$B$45) -> -221625
A19: Energia de processo | B19: =-B4*1000*Premissas!$B$46 -> 0 | C19: =-C4*1000*Premissas!$B$46 -> -20000 | D19: =-D4*1000*Premissas!$B$46 -> -25000 | E19: =-E4*1000*Premissas!$B$46 -> -25000 | F19: =-F4*1000*Premissas!$B$46 -> -25000 | G19: =-G4*1000*Premissas!$B$46 -> -25000 | H19: =-H4*1000*Premissas!$B$46 -> -25000 | I19: =-I4*1000*Premissas!$B$46 -> -25000 | ... N19: =-N4*1000*Premissas!$B$46 -> -25000
A20: MARGEM DE CONTRIBUIÇÃO | B20: =SUM(B12:B19) -> 0 | C20: =SUM(C12:C19) -> 1603178.2 | D20: =SUM(D12:D19) -> 2003972.8 | E20: =SUM(E12:E19) -> 2003972.8 | F20: =SUM(F12:F19) -> 2003972.8 | G20: =SUM(G12:G19) -> 2003972.8 | H20: =SUM(H12:H19) -> 2003972.8 | I20: =SUM(I12:I19) -> 2003972.8 | ... N20: =SUM(N12:N19) -> 2003972.8
A22: Pessoal | B22: 0 | C22: =-Premissas!$B$50 -> -507794.36 | D22: =-Premissas!$B$50 -> -507794.36 | E22: =-Premissas!$B$50 -> -507794.36 | F22: =-Premissas!$B$50 -> -507794.36 | G22: =-Premissas!$B$50 -> -507794.36 | H22: =-Premissas!$B$50 -> -507794.36 | I22: =-Premissas!$B$50 -> -507794.36 | J22: =-Premissas!$B$50 -> -507794.36 | ... N22: =-Premissas!$B$50 -> -507794.36
A23: RT + laboratório externo | B23: 0 | C23: =-(Premissas!$B$51+Premissas!$B$52) -> -100000 | D23: =-(Premissas!$B$51+Premissas!$B$52) -> -100000 | E23: =-(Premissas!$B$51+Premissas!$B$52) -> -100000 | F23: =-(Premissas!$B$51+Premissas!$B$52) -> -100000 | G23: =-(Premissas!$B$51+Premissas!$B$52) -> -100000 | H23: =-(Premissas!$B$51+Premissas!$B$52) -> -100000 | I23: =-(Premissas!$B$51+Premissas!$B$52) -> -100000 | J23: =-(Premissas!$B$51+Premissas!$B$52) -> -100000 | ... N23: =-(Premissas!$B$51+Premissas!$B$52) -> -100000
A24: Administrativas + energia fixa | B24: 0 | C24: =-(Premissas!$B$53+Premissas!$B$54) -> -198000 | D24: =-(Premissas!$B$53+Premissas!$B$54) -> -198000 | E24: =-(Premissas!$B$53+Premissas!$B$54) -> -198000 | F24: =-(Premissas!$B$53+Premissas!$B$54) -> -198000 | G24: =-(Premissas!$B$53+Premissas!$B$54) -> -198000 | H24: =-(Premissas!$B$53+Premissas!$B$54) -> -198000 | I24: =-(Premissas!$B$53+Premissas!$B$54) -> -198000 | J24: =-(Premissas!$B$53+Premissas!$B$54) -> -198000 | ... N24: =-(Premissas!$B$53+Premissas!$B$54) -> -198000
A25: Manutenção + seguros | B25: 0 | C25: =-(Premissas!$B$11*Premissas!$B$8*Premissas!$B$55+Premissas!$B$12*Premissas!$B$8*Premissas!$B$56+Premissas!$B$14*Premissas!$B$57) -> -75491.84 | D25: =-(Premissas!$B$11*Premissas!$B$8*Premissas!$B$55+Premissas!$B$12*Premissas!$B$8*Premissas!$B$56+Premissas!$B$14*Premissas!$B$57) -> -75491.84 | E25: =-(Premissas!$B$11*Premissas!$B$8*Premissas!$B$55+Premissas!$B$12*Premissas!$B$8*Premissas!$B$56+Premissas!$B$14*Premissas!$B$57) -> -75491.84 | F25: =-(Premissas!$B$11*Premissas!$B$8*Premissas!$B$55+Premissas!$B$12*Premissas!$B$8*Premissas!$B$56+Premissas!$B$14*Premissas!$B$57) -> -75491.84 | G25: =-(Premissas!$B$11*Premissas!$B$8*Premissas!$B$55+Premissas!$B$12*Premissas!$B$8*Premissas!$B$56+Premissas!$B$14*Premissas!$B$57) -> -75491.84 | H25: =-(Premissas!$B$11*Premissas!$B$8*Premissas!$B$55+Premissas!$B$12*Premissas!$B$8*Premissas!$B$56+Premissas!$B$14*Premissas!$B$57) -> -75491.84 | I25: =-(Premissas!$B$11*Premissas!$B$8*Premissas!$B$55+Premissas!$B$12*Premissas!$B$8*Premissas!$B$56+Premissas!$B$14*Premissas!$B$57) -> -75491.84 | J25: =-(Premissas!$B$11*Premissas!$B$8*Premissas!$B$55+Premissas!$B$12*Premissas!$B$8*Premissas!$B$56+Premissas!$B$14*Premissas!$B$57) -> -75491.84 | ... N25: =-(Premissas!$B$11*Premissas!$B$8*Premissas!$B$55+Premissas!$B$12*Premissas!$B$8*Premissas!$B$56+Premissas!$B$14*Premissas!$B$57) -> -75491.84
A26: EBITDA | B26: =B20+SUM(B22:B25) -> 0 | C26: =C20+SUM(C22:C25) -> 721892 | D26: =D20+SUM(D22:D25) -> 1122686.6 | E26: =E20+SUM(E22:E25) -> 1122686.6 | F26: =F20+SUM(F22:F25) -> 1122686.6 | G26: =G20+SUM(G22:G25) -> 1122686.6 | H26: =H20+SUM(H22:H25) -> 1122686.6 | I26: =I20+SUM(I22:I25) -> 1122686.6 | ... N26: =N20+SUM(N22:N25) -> 1122686.6
A27: Margem EBITDA | B27: =IF(B12=0,0,B26/B12) -> 0 | C27: =IF(C12=0,0,C26/C12) -> 0.14415525 | D27: =IF(D12=0,0,D26/D12) -> 0.17935221 | E27: =IF(E12=0,0,E26/E12) -> 0.17935221 | F27: =IF(F12=0,0,F26/F12) -> 0.17935221 | G27: =IF(G12=0,0,G26/G12) -> 0.17935221 | H27: =IF(H12=0,0,H26/H12) -> 0.17935221 | I27: =IF(I12=0,0,I26/I12) -> 0.17935221 | ... N27: =IF(N12=0,0,N26/N12) -> 0.17935221
A28: Depreciação | B28: 0 | C28: =-(Premissas!$B$11*Premissas!$B$8/Premissas!$B$61+(Premissas!$B$12+Premissas!$B$13)*Premissas!$B$8/Premissas!$B$62) -> -275662.4 | D28: =-(Premissas!$B$11*Premissas!$B$8/Premissas!$B$61+(Premissas!$B$12+Premissas!$B$13)*Premissas!$B$8/Premissas!$B$62) -> -275662.4 | E28: =-(Premissas!$B$11*Premissas!$B$8/Premissas!$B$61+(Premissas!$B$12+Premissas!$B$13)*Premissas!$B$8/Premissas!$B$62) -> -275662.4 | F28: =-(Premissas!$B$11*Premissas!$B$8/Premissas!$B$61+(Premissas!$B$12+Premissas!$B$13)*Premissas!$B$8/Premissas!$B$62) -> -275662.4 | G28: =-(Premissas!$B$11*Premissas!$B$8/Premissas!$B$61+(Premissas!$B$12+Premissas!$B$13)*Premissas!$B$8/Premissas!$B$62) -> -275662.4 | H28: =-(Premissas!$B$11*Premissas!$B$8/Premissas!$B$61+(Premissas!$B$12+Premissas!$B$13)*Premissas!$B$8/Premissas!$B$62) -> -275662.4 | I28: =-(Premissas!$B$11*Premissas!$B$8/Premissas!$B$61+(Premissas!$B$12+Premissas!$B$13)*Premissas!$B$8/Premissas!$B$62) -> -275662.4 | J28: =-(Premissas!$B$11*Premissas!$B$8/Premissas!$B$61+(Premissas!$B$12+Premissas!$B$13)*Premissas!$B$8/Premissas!$B$62) -> -275662.4 | ... N28: =-(Premissas!$B$11*Premissas!$B$8/Premissas!$B$61+(Premissas!$B$12+Premissas!$B$13)*Premissas!$B$8/Premissas!$B$62) -> -275662.4
A30: Saldo FNE investimento (início) | B30: =Premissas!$B$15 -> 2000000 | C30: =Premissas!$B$15 -> 2000000 | D30: =C30+C32 -> 2000000 | E30: =D30+D32 -> 2000000 | F30: =E30+E32 -> 2000000 | G30: =F30+F32 -> 2000000 | H30: =G30+G32 -> 1750000 | I30: =H30+H32 -> 1500000 | J30: =I30+I32 -> 1250000 | K30: =J30+J32 -> 1000000 | ... N30: =M30+M32 -> 250000
A31: Juros FNE investimento | B31: =-Premissas!$B$15*Premissas!$B$16*Premissas!$B$19 -> -100000 | C31: =-C30*Premissas!$B$16 -> -200000 | D31: =-D30*Premissas!$B$16 -> -200000 | E31: =-E30*Premissas!$B$16 -> -200000 | F31: =-F30*Premissas!$B$16 -> -200000 | G31: =-G30*Premissas!$B$16 -> -200000 | H31: =-H30*Premissas!$B$16 -> -175000 | I31: =-I30*Premissas!$B$16 -> -150000 | J31: =-J30*Premissas!$B$16 -> -125000 | ... N31: =-N30*Premissas!$B$16 -> -25000
A32: Amortização FNE investimento | B32: 0 | C32: 0 | D32: 0 | E32: 0 | F32: 0 | G32: =-Premissas!$B$15/(Premissas!$B$17-Premissas!$B$18) -> -250000 | H32: =-Premissas!$B$15/(Premissas!$B$17-Premissas!$B$18) -> -250000 | I32: =-Premissas!$B$15/(Premissas!$B$17-Premissas!$B$18) -> -250000 | J32: =-Premissas!$B$15/(Premissas!$B$17-Premissas!$B$18) -> -250000 | K32: =-Premissas!$B$15/(Premissas!$B$17-Premissas!$B$18) -> -250000 | L32: =-Premissas!$B$15/(Premissas!$B$17-Premissas!$B$18) -> -250000 | M32: =-Premissas!$B$15/(Premissas!$B$17-Premissas!$B$18) -> -250000 | N32: =-Premissas!$B$15/(Premissas!$B$17-Premissas!$B$18) -> -250000
A33: Juros FNE giro (renovável) | B33: 0 | C33: =-Premissas!$B$60*Premissas!$B$16 -> -60000 | D33: =-Premissas!$B$60*Premissas!$B$16 -> -60000 | E33: =-Premissas!$B$60*Premissas!$B$16 -> -60000 | F33: =-Premissas!$B$60*Premissas!$B$16 -> -60000 | G33: =-Premissas!$B$60*Premissas!$B$16 -> -60000 | H33: =-Premissas!$B$60*Premissas!$B$16 -> -60000 | I33: =-Premissas!$B$60*Premissas!$B$16 -> -60000 | J33: =-Premissas!$B$60*Premissas!$B$16 -> -60000 | ... N33: =-Premissas!$B$60*Premissas!$B$16 -> -60000
A34: SERVIÇO DA DÍVIDA (anos 1-12) | B34: 0 | C34: =-(C31+C32+C33) -> 260000 | D34: =-(D31+D32+D33) -> 260000 | E34: =-(E31+E32+E33) -> 260000 | F34: =-(F31+F32+F33) -> 260000 | G34: =-(G31+G32+G33) -> 510000 | H34: =-(H31+H32+H33) -> 485000 | I34: =-(I31+I32+I33) -> 460000 | J34: =-(J31+J32+J33) -> 435000 | ... N34: =-(N31+N32+N33) -> 335000
A35: Retenção de 5% (cota-parte, fica no caixa) | B35: =-B15*Premissas!$B$36 -> 0 | C35: =-C15*Premissas!$B$36 -> 120575 | D35: =-D15*Premissas!$B$36 -> 150718.75 | E35: =-E15*Premissas!$B$36 -> 150718.75 | F35: =-F15*Premissas!$B$36 -> 150718.75 | G35: =-G15*Premissas!$B$36 -> 150718.75 | H35: =-H15*Premissas!$B$36 -> 150718.75 | I35: =-I15*Premissas!$B$36 -> 150718.75 | ... N35: =-N15*Premissas!$B$36 -> 150718.75
A36: CAIXA PARA A DÍVIDA (EBITDA + retenção) | B36: =B26+B35 -> 0 | C36: =C26+C35 -> 842467 | D36: =D26+D35 -> 1273405.3 | E36: =E26+E35 -> 1273405.3 | F36: =F26+F35 -> 1273405.3 | G36: =G26+G35 -> 1273405.3 | H36: =H26+H35 -> 1273405.3 | I36: =I26+I35 -> 1273405.3 | ... N36: =N26+N35 -> 1273405.3
A37: COBERTURA DA DÍVIDA (DSCR) | C37: =C36/C34 -> 3.2402577 | D37: =D36/D34 -> 4.8977127 | E37: =E36/E34 -> 4.8977127 | F37: =F36/F34 -> 4.8977127 | G37: =G36/G34 -> 2.4968731 | H37: =H36/H34 -> 2.6255779 | I37: =I36/I34 -> 2.7682724 | J37: =J36/J34 -> 2.9273685 | ... N37: =N36/N34 -> 3.8012099
A38: Cobertura operacional SEM a retenção | C38: =C26/C34 -> 2.7765077 | D38: =D26/D34 -> 4.3180252 | E38: =E26/E34 -> 4.3180252 | F38: =F26/F34 -> 4.3180252 | G38: =G26/G34 -> 2.2013462 | H38: =H26/H34 -> 2.3148176 | I38: =I26/I34 -> 2.4406229 | J38: =J26/J34 -> 2.5808886 | ... N38: =N26/N34 -> 3.3513031
A40: Sobras do exercício (após juros e depreciação) | B40: =B26+B28+B31+B33 -> -100000 | C40: =C26+C28+C31+C33 -> 186229.6 | D40: =D26+D28+D31+D33 -> 587024.15 | E40: =E26+E28+E31+E33 -> 587024.15 | F40: =F26+F28+F31+F33 -> 587024.15 | G40: =G26+G28+G31+G33 -> 587024.15 | H40: =H26+H28+H31+H33 -> 612024.15 | I40: =I26+I28+I31+I33 -> 637024.15 | ... N40: =N26+N28+N31+N33 -> 762024.15
A41: Fluxo do projeto (desalavancado) | B41: =-Premissas!$B$14 -> -3831560 | C41: =C26 -> 721892 | D41: =D26 -> 1122686.6 | E41: =E26 -> 1122686.6 | F41: =F26 -> 1122686.6 | G41: =G26 -> 1122686.6 | H41: =H26 -> 1122686.6 | I41: =I26 -> 1122686.6 | J41: =J26 -> 1122686.6 | ... N41: =N26 -> 1122686.6
A42: Fluxo dos cooperados (contrapartida, dívida, retenção) | B42: =-(Premissas!$B$14-Premissas!$B$15)+B31 -> -1931560 | C42: =C26+C31+C32+C33 -> 461892 | D42: =D26+D31+D32+D33 -> 862686.55 | E42: =E26+E31+E32+E33 -> 862686.55 | F42: =F26+F31+F32+F33 -> 862686.55 | G42: =G26+G31+G32+G33 -> 612686.55 | H42: =H26+H31+H32+H33 -> 637686.55 | I42: =I26+I31+I32+I33 -> 662686.55 | J42: =J26+J31+J32+J33 -> 687686.55 | ... N42: =N26+N31+N32+N33 -> 787686.55
A43: Ganho dos apicultores sobre o atravessador | B43: =B4*1000*(Premissas!$B$33-Premissas!$B$37) -> 0 | C43: =C4*1000*(Premissas!$B$33-Premissas!$B$37) -> 11500 | D43: =D4*1000*(Premissas!$B$33-Premissas!$B$37) -> 14375 | E43: =E4*1000*(Premissas!$B$33-Premissas!$B$37) -> 14375 | F43: =F4*1000*(Premissas!$B$33-Premissas!$B$37) -> 14375 | G43: =G4*1000*(Premissas!$B$33-Premissas!$B$37) -> 14375 | H43: =H4*1000*(Premissas!$B$33-Premissas!$B$37) -> 14375 | I43: =I4*1000*(Premissas!$B$33-Premissas!$B$37) -> 14375 | ... N43: =N4*1000*(Premissas!$B$33-Premissas!$B$37) -> 14375

Sheet Resumo
A1: RESUMO · Entreposto Regional (fonte única de números da suíte MHBV 1.0)
A3: Indicador | B3: Valor
A4: Investimento total | B4: =Premissas!$B$14 -> 3831560
A5: FNE investimento | B5: =Premissas!$B$15 -> 2000000
A6: Capital próprio (contrapartida) | B6: =Premissas!$B$14-Premissas!$B$15 -> 1831560
A7: FNE giro (renovável) | B7: =Premissas!$B$60 -> 600000
A8: Total financiado FNE | B8: =Premissas!$B$15+Premissas!$B$60 -> 2600000
A9: Taxa FNE no modelo | B9: =Premissas!$B$16 -> 0.1
A10: Volume no regime (ano 2 em diante) | B10: =Fluxo!E4 -> 250
A11: Receita bruta no regime (250 t) | B11: =Fluxo!E12 -> 6259675
A12: EBITDA no regime (250 t) | B12: =Fluxo!E26 -> 1122686.6
A13: Margem EBITDA no regime | B13: =Fluxo!E27 -> 0.17935221
A14: Preço ao cooperado (R$/kg) | B14: =Premissas!$B$33 -> 12.0575
A15: Compra anual de mel no regime | B15: =-Fluxo!E15 -> 3014375
A16: Retenção de 5% no regime (R$/ano) | B16: =Fluxo!E35 -> 150718.75
A17: COBERTURA MÍNIMA DA DÍVIDA – anos 1 a 12 | B17: =MIN(Fluxo!C37:N37) -> 2.4968731
A18: Ano da cobertura mínima | B18: =MATCH(MIN(Fluxo!C37:N37),Fluxo!C37:N37,0) -> 5
A19: Cobertura média – anos 5 a 12 (amortização) | B19: =AVERAGE(Fluxo!G37:N37) -> 3.071244
A20: Cobertura operacional mínima SEM retenção | B20: =MIN(Fluxo!C38:N38) -> 2.2013462
A21: TIR do projeto (12 anos, sem valor residual) | B21: =IRR(Fluxo!B41:N41) -> 0.25223133
A22: VPL do projeto | B22: =NPV(Premissas!$B$64,Fluxo!C41:N41)+Fluxo!B41 -> 3453721.5
A23: TIR dos cooperados | B23: =IFERROR(IRR(Fluxo!B42:N42),"negativa") -> 0.35263725
A24: Ganho dos apicultores sobre o atravessador (12 anos) | B24: =SUM(Fluxo!C43:N43) -> 169625
A25: Quadro fixo (pessoas) | B25: =Pessoal!C14 -> 10
A26: Sobra distribuível por kg no ano 6 (após Reserva 10% + FATES 5%) | B26: =Fluxo!H40*0.85/(Fluxo!H4*1000) -> 2.0808821
A27: Preço efetivo ao cooperado no ano 6 (adiantamento + sobra, R$/kg) | B27: =Premissas!$B$33+B26 -> 14.138382
A28: Piso BNB usado no projeto: cobertura ≥ 1,5x com mel −20% (ver Cenarios_BNB). Base D1 (07/10/2026): obra R$ 1,79 mi, investimento R$ 3,83 mi. Todos os custos marcados como ESTIMATIVA/PREMISSA devem ser trocados por cotação real.

Sheet Giro
A1: PLANO DE GIRO · ano de regime (250 t)
A3: Item | B3: Valor (R$) | C3: Observação
A4: Compra anual de mel | B4: =-Fluxo!E15 -> 3014375 | C4: Volume × preço ao cooperado.
A5: Necessidade bruta (estoque de safra ≈ 49% da compra) | B5: =B4*0.4929 -> 1485785.4 | C5: Método do plano de 29/09 (49% da compra anual).
A6: − granel vendido logo (40%) | B6: =-B5*(1-Premissas!$B$27) -> -594314.18 | C6: Só o estoque de sachê fica parado.
A7: Estoque parado de sachê | B7: =B5+B6 -> 891471.26
A8: − pagamento escalonado (30% só no fim do exercício) | B8: =-B7*0.28 -> -249611.95 | C8: 50% na entrega + 20% em 90 dias.
A9: Necessidade líquida a financiar | B9: =B7+B8 -> 641859.31 | C9: Coberta pelo FNE giro + retenção.
A10: Coberta por: FNE giro renovável | B10: =Premissas!$B$60 -> 600000 | C10: Garantia: penhor do estoque de sachê.
A11: Coberta por: retenção de 5% (1º ano de regime) | B11: =B9-B10 -> 41859.309 | C11: Retenção anual no regime em Resumo.
A12: Juros anuais do giro (entram na dívida) | B12: =Premissas!$B$60*Premissas!$B$16 -> 60000 | C12: O principal volta com a venda do estoque.

Sheet Cenarios_BNB
A1: CENÁRIOS BNB · valores gravados pelo recálculo do próprio modelo (LibreOffice) em 07/10/2026 · base D1 (obra R$ 1,79 mi; investimento R$ 3,83 mi)
A3: Cenário | B3: Cobertura mín. | C3: Ano | D3: Sem retenção | E3: TIR projeto | F3: TIR cooperados | G3: EBITDA regime
A4: BASE (250 t · sachê R$ 30 · granel R$ 18,55 · juros 10%) | B4: 2.4969 | C4: 5 | D4: 2.2013 | E4: 0.2522 | F4: 0.3526 | G4: 1122686.6
A5: Mel −20% (venda e cooperado) ← PISO BNB ≥ 1,50x | B5: 1.5108 | C5: 5 | D5: 1.2743 | E5: 0.1158 | F5: 0.0795 | G5: 649912
A6: Volume −20% (200 t) | B6: 1.6519 | C6: 5 | D6: 1.4155 | E6: 0.1385 | F6: 0.1292 | G6: 721892
A7: Preço −10% e volume −10% | B7: 1.6306 | C7: 5 | D7: 1.3913 | E7: 0.1347 | F7: 0.1211 | G7: 709540.73
A8: Juros FNE 12,45% a.a. | B8: 2.2196 | C8: 5 | D8: 1.9569 | E8: 0.2522 | F8: 0.3165 | G8: 1122686.6
A9: Juros FNE 7,65% a.a. | B9: 2.8367 | C9: 5 | D9: 2.501 | E9: 0.2522 | F9: 0.3881 | G9: 1122686.6
A10: Sachê a R$ 25/kg (sem mexer no granel) | B10: 1.2946 | C10: 5 | D10: 0.8899 | E10: 0.0679 | F10: -0.0446 | G10: 509524.05
A11: Investimento +20% (R$ 4,60 mi) | B11: 2.4673 | C11: 5 | D11: 2.1717 | E11: 0.1992 | F11: 0.2367 | G11: 1107588.2
A13: Leitura: a cobertura mínima ocorre no ano 5 (1ª amortização do FNE investimento). Piso adotado: ≥ 1,50x com mel −20% → 1,51x (margem 0,01x; sem retenção 1,27x — a retenção de 5% é estrutural). Ponto fraco: preço do sachê (R$ 25/kg → 1,29x) — exige cartas de intenção de compra antes do protocolo.
A14: Decisões: 30/09/2026 FNE investimento R$ 2,0 mi + giro R$ 0,6 mi; cooperado 65% do granel PAA/Conab-CE · 07/10/2026 (D1) obra R$ 1,79 mi → capital próprio R$ 1,83 mi.
